<sdf version='1.7'>
  <world name='default'>
    <physics type='ode'>
      <ode>
        <solver>
          <type>quick</type>
          <iters>100</iters>
          <sor>1</sor>
          <use_dynamic_moi_rescaling>0</use_dynamic_moi_rescaling>
        </solver>
        <constraints>
          <cfm>0</cfm>
          <erp>0.9</erp>
          <contact_max_correcting_vel>0.1</contact_max_correcting_vel>
          <contact_surface_layer>0</contact_surface_layer>
        </constraints>
      </ode>
      <real_time_update_rate>-1</real_time_update_rate>
      <max_step_size>0.001</max_step_size>
      <real_time_factor>1</real_time_factor>
    </physics>
    <light name='sun' type='directional'>
      <cast_shadows>1</cast_shadows>
      <pose>0 0 10 0 -0 0</pose>
      <diffuse>0.8 0.8 0.8 1</diffuse>
      <specular>0.2 0.2 0.2 1</specular>
      <attenuation>
        <range>1000</range>
        <constant>0.9</constant>
        <linear>0.01</linear>
        <quadratic>0.001</quadratic>
      </attenuation>
      <direction>-0.5 0.1 -0.9</direction>
      <spot>
        <inner_angle>0</inner_angle>
        <outer_angle>0</outer_angle>
        <falloff>0</falloff>
      </spot>
    </light>
    <model name='iris'>
      <frame name='iris_demo::__model__' attached_to='iris_demo::iris::base_link'>
        <pose relative_to='__model__'>0 0 0 0 -0 0</pose>
      </frame>
      <frame name='iris_demo::iris::__model__' attached_to='iris_demo::iris::base_link'>
        <pose relative_to='iris_demo::__model__'>0 0 0.194923 0 -0 0</pose>
      </frame>
      <link name='iris_demo::iris::base_link'>
        <velocity_decay>
          <linear>0</linear>
          <angular>0</angular>
        </velocity_decay>
        <inertial>
          <pose>0 0 0 0 -0 0</pose>
          <mass>1.5</mass>
          <inertia>
            <ixx>0.008</ixx>
            <ixy>0</ixy>
            <ixz>0</ixz>
            <iyy>0.015</iyy>
            <iyz>0</iyz>
            <izz>0.017</izz>
          </inertia>
        </inertial>
        <collision name='base_link_collision'>
          <pose>0 0 -0.08 0 -0 0</pose>
          <geometry>
            <box>
              <size>0.47 0.47 0.23</size>
            </box>
          </geometry>
          <surface>
            <contact>
              <ode>
                <max_vel>100</max_vel>
                <min_depth>0.001</min_depth>
              </ode>
            </contact>
            <friction>
              <ode>
                <mu>100000</mu>
                <mu2>100000</mu2>
              </ode>
              <torsional>
                <ode/>
              </torsional>
            </friction>
            <bounce/>
          </surface>
          <max_contacts>10</max_contacts>
        </collision>
        <visual name='base_link_visual'>
          <geometry>
            <mesh>
              <uri>model://iris_with_standoffs/meshes/iris.dae</uri>
            </mesh>
          </geometry>
          <material>
            <script>
              <name>Gazebo/DarkGrey</name>
              <uri>__default__</uri>
            </script>
          </material>
        </visual>
        <visual name='front_left_leg_visual'>
          <pose>0.123 0.22 -0.11 0 -0 0</pose>
          <geometry>
            <cylinder>
              <radius>0.005</radius>
              <length>0.17</length>
            </cylinder>
          </geometry>
          <material>
            <script>
              <name>Gazebo/FlatBlack</name>
              <uri>file://media/materials/scripts/gazebo.material</uri>
            </script>
          </material>
        </visual>
        <visual name='front_right_leg_visual'>
          <pose>0.123 -0.22 -0.11 0 -0 0</pose>
          <geometry>
            <cylinder>
              <radius>0.005</radius>
              <length>0.17</length>
            </cylinder>
          </geometry>
          <material>
            <script>
              <name>Gazebo/FlatBlack</name>
              <uri>file://media/materials/scripts/gazebo.material</uri>
            </script>
          </material>
        </visual>
        <visual name='rear_left_leg_visual'>
          <pose>-0.14 0.21 -0.11 0 -0 0</pose>
          <geometry>
            <cylinder>
              <radius>0.005</radius>
              <length>0.17</length>
            </cylinder>
          </geometry>
          <material>
            <script>
              <name>Gazebo/FlatBlack</name>
              <uri>file://media/materials/scripts/gazebo.material</uri>
            </script>
          </material>
        </visual>
        <visual name='rear_right_leg_visual'>
          <pose>-0.14 -0.21 -0.11 0 -0 0</pose>
          <geometry>
            <cylinder>
              <radius>0.005</radius>
              <length>0.17</length>
            </cylinder>
          </geometry>
          <material>
            <script>
              <name>Gazebo/FlatBlack</name>
              <uri>file://media/materials/scripts/gazebo.material</uri>
            </script>
          </material>
        </visual>
        <pose relative_to='iris_demo::iris::__model__'>0 0 0 0 -0 0</pose>
        <self_collide>0</self_collide>
        <enable_wind>0</enable_wind>
        <kinematic>0</kinematic>
      </link>
      <link name='iris_demo::iris::iris/ground_truth/odometry_sensorgt_link'>
        <pose relative_to='iris_demo::iris::__model__'>0 0 0 0 -0 0</pose>
        <inertial>
          <pose>0 0 0 0 -0 0</pose>
          <mass>0.15</mass>
          <inertia>
            <ixx>0.0001</ixx>
            <ixy>0</ixy>
            <ixz>0</ixz>
            <iyy>0.0002</iyy>
            <iyz>0</iyz>
            <izz>0.0002</izz>
          </inertia>
        </inertial>
        <self_collide>0</self_collide>
        <enable_wind>0</enable_wind>
        <kinematic>0</kinematic>
      </link>
      <joint name='iris_demo::iris::iris/ground_truth/odometry_sensorgt_joint' type='revolute'>
        <child>iris_demo::iris::iris/ground_truth/odometry_sensorgt_link</child>
        <parent>iris_demo::iris::base_link</parent>
        <axis>
          <xyz expressed_in='iris_demo::iris::__model__'>0 0 1</xyz>
          <limit>
            <lower>0</lower>
            <upper>0</upper>
            <effort>0</effort>
            <velocity>0</velocity>
          </limit>
          <dynamics>
            <damping>1</damping>
            <spring_reference>0</spring_reference>
            <spring_stiffness>0</spring_stiffness>
          </dynamics>
        </axis>
        <physics>
          <ode>
            <implicit_spring_damper>1</implicit_spring_damper>
            <limit>
              <cfm>0</cfm>
              <erp>0.2</erp>
            </limit>
          </ode>
        </physics>
      </joint>
      <link name='iris_demo::iris::iris/imu_link'>
        <inertial>
          <pose>0 0 0 0 -0 0</pose>
          <mass>0.15</mass>
          <inertia>
            <ixx>1e-05</ixx>
            <ixy>0</ixy>
            <ixz>0</ixz>
            <iyy>2e-05</iyy>
            <iyz>0</iyz>
            <izz>2e-05</izz>
          </inertia>
        </inertial>
        <sensor name='imu_sensor' type='imu'>
          <pose>0 0 0 -3.14159 -0 0</pose>
          <always_on>1</always_on>
          <update_rate>1000</update_rate>
          <imu/>
        </sensor>
        <pose relative_to='iris_demo::iris::__model__'>0 0 0 0 -0 0</pose>
        <self_collide>0</self_collide>
        <enable_wind>0</enable_wind>
        <kinematic>0</kinematic>
      </link>
      <joint name='iris_demo::iris::iris/imu_joint' type='revolute'>
        <child>iris_demo::iris::iris/imu_link</child>
        <parent>iris_demo::iris::base_link</parent>
        <axis>
          <xyz expressed_in='iris_demo::iris::__model__'>0 0 1</xyz>
          <limit>
            <lower>0</lower>
            <upper>0</upper>
            <effort>0</effort>
            <velocity>0</velocity>
          </limit>
          <dynamics>
            <damping>1</damping>
            <spring_reference>0</spring_reference>
            <spring_stiffness>0</spring_stiffness>
          </dynamics>
        </axis>
        <physics>
          <ode>
            <implicit_spring_damper>1</implicit_spring_damper>
            <limit>
              <cfm>0</cfm>
              <erp>0.2</erp>
            </limit>
          </ode>
        </physics>
      </joint>
      <link name='iris_demo::iris::rotor_0'>
        <pose relative_to='iris_demo::iris::__model__'>0.13 -0.22 0.023 0 -0 0</pose>
        <inertial>
          <pose>0 0 0 0 -0 0</pose>
          <mass>0.025</mass>
          <inertia>
            <ixx>9.75e-06</ixx>
            <ixy>0</ixy>
            <ixz>0</ixz>
            <iyy>0.000166704</iyy>
            <iyz>0</iyz>
            <izz>0.000167604</izz>
          </inertia>
        </inertial>
        <collision name='rotor_0_collision'>
          <pose>0 0 0 0 -0 0</pose>
          <geometry>
            <cylinder>
              <length>0.005</length>
              <radius>0.1</radius>
            </cylinder>
          </geometry>
          <surface>
            <contact>
              <ode/>
            </contact>
            <friction>
              <ode/>
              <torsional>
                <ode/>
              </torsional>
            </friction>
            <bounce/>
          </surface>
          <max_contacts>10</max_contacts>
        </collision>
        <visual name='rotor_0_visual'>
          <pose>0 0 0 0 -0 0</pose>
          <geometry>
            <mesh>
              <scale>1 1 1</scale>
              <uri>model://iris_with_standoffs/meshes/iris_prop_ccw.dae</uri>
            </mesh>
          </geometry>
          <material>
            <script>
              <name>Gazebo/Blue</name>
              <uri>__default__</uri>
            </script>
          </material>
        </visual>
        <gravity>1</gravity>
        <velocity_decay/>
        <self_collide>0</self_collide>
        <enable_wind>0</enable_wind>
        <kinematic>0</kinematic>
      </link>
      <joint name='iris_demo::iris::rotor_0_joint' type='revolute'>
        <child>iris_demo::iris::rotor_0</child>
        <parent>iris_demo::iris::base_link</parent>
        <axis>
          <xyz expressed_in='iris_demo::iris::__model__'>0 0 1</xyz>
          <limit>
            <lower>-1e+16</lower>
            <upper>1e+16</upper>
          </limit>
          <dynamics>
            <damping>0.004</damping>
            <spring_reference>0</spring_reference>
            <spring_stiffness>0</spring_stiffness>
          </dynamics>
        </axis>
        <physics>
          <ode>
            <implicit_spring_damper>1</implicit_spring_damper>
            <limit>
              <cfm>0</cfm>
              <erp>0.2</erp>
            </limit>
          </ode>
        </physics>
      </joint>
      <link name='iris_demo::iris::rotor_1'>
        <pose relative_to='iris_demo::iris::__model__'>-0.13 0.2 0.023 0 -0 0</pose>
        <inertial>
          <pose>0 0 0 0 -0 0</pose>
          <mass>0.025</mass>
          <inertia>
            <ixx>9.75e-06</ixx>
            <ixy>0</ixy>
            <ixz>0</ixz>
            <iyy>0.000166704</iyy>
            <iyz>0</iyz>
            <izz>0.000167604</izz>
          </inertia>
        </inertial>
        <collision name='rotor_1_collision'>
          <pose>0 0 0 0 -0 0</pose>
          <geometry>
            <cylinder>
              <length>0.005</length>
              <radius>0.1</radius>
            </cylinder>
          </geometry>
          <surface>
            <contact>
              <ode/>
            </contact>
            <friction>
              <ode/>
              <torsional>
                <ode/>
              </torsional>
            </friction>
            <bounce/>
          </surface>
          <max_contacts>10</max_contacts>
        </collision>
        <visual name='rotor_1_visual'>
          <pose>0 0 0 0 -0 0</pose>
          <geometry>
            <mesh>
              <scale>1 1 1</scale>
              <uri>model://iris_with_standoffs/meshes/iris_prop_ccw.dae</uri>
            </mesh>
          </geometry>
          <material>
            <script>
              <name>Gazebo/DarkGrey</name>
              <uri>__default__</uri>
            </script>
          </material>
        </visual>
        <gravity>1</gravity>
        <velocity_decay/>
        <self_collide>0</self_collide>
        <enable_wind>0</enable_wind>
        <kinematic>0</kinematic>
      </link>
      <joint name='iris_demo::iris::rotor_1_joint' type='revolute'>
        <child>iris_demo::iris::rotor_1</child>
        <parent>iris_demo::iris::base_link</parent>
        <axis>
          <xyz expressed_in='iris_demo::iris::__model__'>0 0 1</xyz>
          <limit>
            <lower>-1e+16</lower>
            <upper>1e+16</upper>
          </limit>
          <dynamics>
            <damping>0.004</damping>
            <spring_reference>0</spring_reference>
            <spring_stiffness>0</spring_stiffness>
          </dynamics>
        </axis>
        <physics>
          <ode>
            <implicit_spring_damper>1</implicit_spring_damper>
            <limit>
              <cfm>0</cfm>
              <erp>0.2</erp>
            </limit>
          </ode>
        </physics>
      </joint>
      <link name='iris_demo::iris::rotor_2'>
        <pose relative_to='iris_demo::iris::__model__'>0.13 0.22 0.023 0 -0 0</pose>
        <inertial>
          <pose>0 0 0 0 -0 0</pose>
          <mass>0.025</mass>
          <inertia>
            <ixx>9.75e-06</ixx>
            <ixy>0</ixy>
            <ixz>0</ixz>
            <iyy>0.000166704</iyy>
            <iyz>0</iyz>
            <izz>0.000167604</izz>
          </inertia>
        </inertial>
        <collision name='rotor_2_collision'>
          <pose>0 0 0 0 -0 0</pose>
          <geometry>
            <cylinder>
              <length>0.005</length>
              <radius>0.1</radius>
            </cylinder>
          </geometry>
          <surface>
            <contact>
              <ode/>
            </contact>
            <friction>
              <ode/>
              <torsional>
                <ode/>
              </torsional>
            </friction>
            <bounce/>
          </surface>
          <max_contacts>10</max_contacts>
        </collision>
        <visual name='rotor_2_visual'>
          <pose>0 0 0 0 -0 0</pose>
          <geometry>
            <mesh>
              <scale>1 1 1</scale>
              <uri>model://iris_with_standoffs/meshes/iris_prop_cw.dae</uri>
            </mesh>
          </geometry>
          <material>
            <script>
              <name>Gazebo/Blue</name>
              <uri>__default__</uri>
            </script>
          </material>
        </visual>
        <gravity>1</gravity>
        <velocity_decay/>
        <self_collide>0</self_collide>
        <enable_wind>0</enable_wind>
        <kinematic>0</kinematic>
      </link>
      <joint name='iris_demo::iris::rotor_2_joint' type='revolute'>
        <child>iris_demo::iris::rotor_2</child>
        <parent>iris_demo::iris::base_link</parent>
        <axis>
          <xyz expressed_in='iris_demo::iris::__model__'>0 0 1</xyz>
          <limit>
            <lower>-1e+16</lower>
            <upper>1e+16</upper>
          </limit>
          <dynamics>
            <damping>0.004</damping>
            <spring_reference>0</spring_reference>
            <spring_stiffness>0</spring_stiffness>
          </dynamics>
        </axis>
        <physics>
          <ode>
            <implicit_spring_damper>1</implicit_spring_damper>
            <limit>
              <cfm>0</cfm>
              <erp>0.2</erp>
            </limit>
          </ode>
        </physics>
      </joint>
      <link name='iris_demo::iris::rotor_3'>
        <pose relative_to='iris_demo::iris::__model__'>-0.13 -0.2 0.023 0 -0 0</pose>
        <inertial>
          <pose>0 0 0 0 -0 0</pose>
          <mass>0.025</mass>
          <inertia>
            <ixx>9.75e-06</ixx>
            <ixy>0</ixy>
            <ixz>0</ixz>
            <iyy>0.000166704</iyy>
            <iyz>0</iyz>
            <izz>0.000167604</izz>
          </inertia>
        </inertial>
        <collision name='rotor_3_collision'>
          <pose>0 0 0 0 -0 0</pose>
          <geometry>
            <cylinder>
              <length>0.005</length>
              <radius>0.1</radius>
            </cylinder>
          </geometry>
          <surface>
            <contact>
              <ode/>
            </contact>
            <friction>
              <ode/>
              <torsional>
                <ode/>
              </torsional>
            </friction>
            <bounce/>
          </surface>
          <max_contacts>10</max_contacts>
        </collision>
        <visual name='rotor_3_visual'>
          <pose>0 0 0 0 -0 0</pose>
          <geometry>
            <mesh>
              <scale>1 1 1</scale>
              <uri>model://iris_with_standoffs/meshes/iris_prop_cw.dae</uri>
            </mesh>
          </geometry>
          <material>
            <script>
              <name>Gazebo/DarkGrey</name>
              <uri>__default__</uri>
            </script>
          </material>
        </visual>
        <gravity>1</gravity>
        <velocity_decay/>
        <self_collide>0</self_collide>
        <enable_wind>0</enable_wind>
        <kinematic>0</kinematic>
      </link>
      <joint name='iris_demo::iris::rotor_3_joint' type='revolute'>
        <child>iris_demo::iris::rotor_3</child>
        <parent>iris_demo::iris::base_link</parent>
        <axis>
          <xyz expressed_in='iris_demo::iris::__model__'>0 0 1</xyz>
          <limit>
            <lower>-1e+16</lower>
            <upper>1e+16</upper>
          </limit>
          <dynamics>
            <damping>0.004</damping>
            <spring_reference>0</spring_reference>
            <spring_stiffness>0</spring_stiffness>
          </dynamics>
        </axis>
        <physics>
          <ode>
            <implicit_spring_damper>1</implicit_spring_damper>
            <limit>
              <cfm>0</cfm>
              <erp>0.2</erp>
            </limit>
          </ode>
        </physics>
      </joint>
      <static>0</static>
      <frame name='iris_demo::gimbal_small_2d::__model__' attached_to='iris_demo::gimbal_small_2d::base_link'>
        <pose relative_to='iris_demo::__model__'>0 -0.01 0.07 1.57 -0 1.57</pose>
      </frame>
      <link name='iris_demo::gimbal_small_2d::base_link'>
        <inertial>
          <mass>0.2</mass>
          <inertia>
            <ixx>0.0001</ixx>
            <ixy>0</ixy>
            <ixz>0</ixz>
            <iyy>0.0001</iyy>
            <iyz>0</iyz>
            <izz>0.0001</izz>
          </inertia>
          <pose>0 0 0 0 -0 0</pose>
        </inertial>
        <visual name='base_main_viz'>
          <geometry>
            <mesh>
              <scale>0.001 0.001 0.001</scale>
              <uri>model://gimbal_small_2d/meshes/base_main.dae</uri>
            </mesh>
          </geometry>
          <material>
            <script>
              <uri>file://media/materials/scripts/gazebo.material</uri>
              <name>Gazebo/FlatBlack</name>
            </script>
          </material>
        </visual>
        <visual name='base_arm_viz'>
          <geometry>
            <mesh>
              <scale>0.001 0.001 0.001</scale>
              <uri>model://gimbal_small_2d/meshes/base_arm.dae</uri>
            </mesh>
          </geometry>
          <material>
            <script>
              <uri>file://media/materials/scripts/gazebo.material</uri>
              <name>Gazebo/FlatBlack</name>
            </script>
          </material>
        </visual>
        <collision name='base_col'>
          <pose>0.01 0.075 -0.025 0 -0 0</pose>
          <geometry>
            <box>
              <size>0.1 0.05 0.15</size>
            </box>
          </geometry>
          <surface>
            <friction>
              <ode>
                <mu>1</mu>
                <mu2>1</mu2>
                <fdir1>0 0 0</fdir1>
                <slip1>0</slip1>
                <slip2>0</slip2>
              </ode>
              <torsional>
                <ode/>
              </torsional>
            </friction>
            <contact>
              <ode/>
            </contact>
            <bounce/>
          </surface>
          <max_contacts>10</max_contacts>
        </collision>
        <pose relative_to='iris_demo::gimbal_small_2d::__model__'>0 0 0 0 -0 0</pose>
        <self_collide>0</self_collide>
        <enable_wind>0</enable_wind>
        <kinematic>0</kinematic>
      </link>
      <link name='iris_demo::gimbal_small_2d::tilt_link'>
        <inertial>
          <mass>0.01</mass>
          <inertia>
            <ixx>1e-05</ixx>
            <ixy>0</ixy>
            <ixz>0</ixz>
            <iyy>1e-05</iyy>
            <iyz>0</iyz>
            <izz>1e-05</izz>
          </inertia>
          <pose>0 0 0 0 -0 0</pose>
        </inertial>
        <visual name='tilt_viz'>
          <pose>0 0 -0.005 0 -0 0</pose>
          <geometry>
            <mesh>
              <scale>0.001 0.001 0.001</scale>
              <uri>model://gimbal_small_2d/meshes/tilt.dae</uri>
            </mesh>
          </geometry>
          <material>
            <script>
              <uri>file://media/materials/scripts/gazebo.material</uri>
              <name>Gazebo/Grey</name>
            </script>
          </material>
        </visual>
        <collision name='tilt_col'>
          <pose>0 0 -0.005 0 -0 0</pose>
          <geometry>
            <mesh>
              <scale>0.001 0.001 0.001</scale>
              <uri>model://gimbal_small_2d/meshes/tilt.dae</uri>
            </mesh>
          </geometry>
          <max_contacts>10</max_contacts>
          <surface>
            <contact>
              <ode/>
            </contact>
            <bounce/>
            <friction>
              <torsional>
                <ode/>
              </torsional>
              <ode/>
            </friction>
          </surface>
        </collision>
        <visual name='camera_viz'>
          <pose>0 0 0.02 0 -0 0</pose>
          <geometry>
            <cylinder>
              <radius>0.025</radius>
              <length>0.05</length>
            </cylinder>
          </geometry>
          <material>
            <script>
              <uri>file://media/materials/scripts/gazebo.material</uri>
              <name>Gazebo/Grey</name>
            </script>
          </material>
        </visual>
        <collision name='camera_col'>
          <pose>0 0 0.02 0 -0 0</pose>
          <geometry>
            <cylinder>
              <radius>0.025</radius>
              <length>0.05</length>
            </cylinder>
          </geometry>
          <max_contacts>10</max_contacts>
          <surface>
            <contact>
              <ode/>
            </contact>
            <bounce/>
            <friction>
              <torsional>
                <ode/>
              </torsional>
              <ode/>
            </friction>
          </surface>
        </collision>
        <sensor name='camera' type='camera'>
          <pose>0 0 0 -1.57 -1.57 0</pose>
          <camera>
            <horizontal_fov>2</horizontal_fov>
            <image>
              <width>640</width>
              <height>480</height>
            </image>
            <clip>
              <near>0.05</near>
              <far>15000</far>
            </clip>
          </camera>
          <always_on>1</always_on>
          <update_rate>10</update_rate>
          <visualize>1</visualize>
        </sensor>
        <pose relative_to='iris_demo::gimbal_small_2d::__model__'>0 0 0 0 -0 0</pose>
        <self_collide>0</self_collide>
        <enable_wind>0</enable_wind>
        <kinematic>0</kinematic>
      </link>
      <joint name='iris_demo::gimbal_small_2d::tilt_joint' type='revolute'>
        <parent>iris_demo::gimbal_small_2d::base_link</parent>
        <child>iris_demo::gimbal_small_2d::tilt_link</child>
        <physics>
          <ode>
            <implicit_spring_damper>1</implicit_spring_damper>
            <limit>
              <cfm>0</cfm>
              <erp>0.2</erp>
            </limit>
          </ode>
        </physics>
        <axis>
          <xyz expressed_in='iris_demo::gimbal_small_2d::__model__'>1 0 0</xyz>
          <dynamics>
            <damping>0.5</damping>
            <spring_reference>0</spring_reference>
            <spring_stiffness>0</spring_stiffness>
          </dynamics>
          <limit>
            <lower>-0.1</lower>
            <upper>3.14159</upper>
            <effort>10</effort>
            <velocity>-1</velocity>
          </limit>
        </axis>
        <pose>0 0 0.02 0 -0 0</pose>
      </joint>
      <plugin name='gimbal_small_2d' filename='libGimbalSmall2dPlugin.so'>
        <joint>iris_demo::gimbal_small_2d::tilt_joint</joint>
      </plugin>
      <joint name='iris_demo::iris_gimbal_mount' type='revolute'>
        <parent>iris_demo::iris::base_link</parent>
        <child>iris_demo::gimbal_small_2d::base_link</child>
        <axis>
          <limit>
            <lower>0</lower>
            <upper>0</upper>
          </limit>
          <xyz expressed_in='iris_demo::__model__'>0 0 1</xyz>
          <dynamics>
            <spring_reference>0</spring_reference>
            <spring_stiffness>0</spring_stiffness>
          </dynamics>
        </axis>
      </joint>
      <plugin name='rotor_0_blade_1' filename='libLiftDragPlugin.so'>
        <a0>0.1</a0>
        <alpha_stall>1.4</alpha_stall>
        <cla>0.2500</cla>
        <cda>0.10</cda>
        <cma>0.00</cma>
        <cla_stall>-0.025</cla_stall>
        <cda_stall>0.0</cda_stall>
        <cma_stall>0.0</cma_stall>
        <area>0.2</area>
        <air_density>1.2041</air_density>
        <cp>0.084 0 0</cp>
        <forward>0 1 0</forward>
        <upward>0 0 1</upward>
        <link_name>iris_demo::iris::rotor_0</link_name>
      </plugin>
      <plugin name='rotor_0_blade_2' filename='libLiftDragPlugin.so'>
        <a0>0.1</a0>
        <alpha_stall>1.4</alpha_stall>
        <cla>0.2500</cla>
        <cda>0.10</cda>
        <cma>0.00</cma>
        <cla_stall>-0.025</cla_stall>
        <cda_stall>0.0</cda_stall>
        <cma_stall>0.0</cma_stall>
        <area>0.2</area>
        <air_density>1.2041</air_density>
        <cp>-0.084 0 0</cp>
        <forward>0 -1 0</forward>
        <upward>0 0 1</upward>
        <link_name>iris_demo::iris::rotor_0</link_name>
      </plugin>
      <plugin name='rotor_1_blade_1' filename='libLiftDragPlugin.so'>
        <a0>0.1</a0>
        <alpha_stall>1.4</alpha_stall>
        <cla>0.2500</cla>
        <cda>0.10</cda>
        <cma>0.00</cma>
        <cla_stall>-0.025</cla_stall>
        <cda_stall>0.0</cda_stall>
        <cma_stall>0.0</cma_stall>
        <area>0.2</area>
        <air_density>1.2041</air_density>
        <cp>0.084 0 0</cp>
        <forward>0 1 0</forward>
        <upward>0 0 1</upward>
        <link_name>iris_demo::iris::rotor_1</link_name>
      </plugin>
      <plugin name='rotor_1_blade_2' filename='libLiftDragPlugin.so'>
        <a0>0.1</a0>
        <alpha_stall>1.4</alpha_stall>
        <cla>0.2500</cla>
        <cda>0.10</cda>
        <cma>0.00</cma>
        <cla_stall>-0.025</cla_stall>
        <cda_stall>0.0</cda_stall>
        <cma_stall>0.0</cma_stall>
        <area>0.2</area>
        <air_density>1.2041</air_density>
        <cp>-0.084 0 0</cp>
        <forward>0 -1 0</forward>
        <upward>0 0 1</upward>
        <link_name>iris_demo::iris::rotor_1</link_name>
      </plugin>
      <plugin name='rotor_2_blade_1' filename='libLiftDragPlugin.so'>
        <a0>0.1</a0>
        <alpha_stall>1.4</alpha_stall>
        <cla>0.2500</cla>
        <cda>0.10</cda>
        <cma>0.00</cma>
        <cla_stall>-0.025</cla_stall>
        <cda_stall>0.0</cda_stall>
        <cma_stall>0.0</cma_stall>
        <area>0.2</area>
        <air_density>1.2041</air_density>
        <cp>0.084 0 0</cp>
        <forward>0 -1 0</forward>
        <upward>0 0 1</upward>
        <link_name>iris_demo::iris::rotor_2</link_name>
      </plugin>
      <plugin name='rotor_2_blade_2' filename='libLiftDragPlugin.so'>
        <a0>0.1</a0>
        <alpha_stall>1.4</alpha_stall>
        <cla>0.2500</cla>
        <cda>0.10</cda>
        <cma>0.00</cma>
        <cla_stall>-0.025</cla_stall>
        <cda_stall>0.0</cda_stall>
        <cma_stall>0.0</cma_stall>
        <area>0.2</area>
        <air_density>1.2041</air_density>
        <cp>-0.084 0 0</cp>
        <forward>0 1 0</forward>
        <upward>0 0 1</upward>
        <link_name>iris_demo::iris::rotor_2</link_name>
      </plugin>
      <plugin name='rotor_3_blade_1' filename='libLiftDragPlugin.so'>
        <a0>0.1</a0>
        <alpha_stall>1.4</alpha_stall>
        <cla>0.2500</cla>
        <cda>0.10</cda>
        <cma>0.00</cma>
        <cla_stall>-0.025</cla_stall>
        <cda_stall>0.0</cda_stall>
        <cma_stall>0.0</cma_stall>
        <area>0.2</area>
        <air_density>1.2041</air_density>
        <cp>0.084 0 0</cp>
        <forward>0 -1 0</forward>
        <upward>0 0 1</upward>
        <link_name>iris_demo::iris::rotor_3</link_name>
      </plugin>
      <plugin name='rotor_3_blade_2' filename='libLiftDragPlugin.so'>
        <a0>0.1</a0>
        <alpha_stall>1.4</alpha_stall>
        <cla>0.2500</cla>
        <cda>0.10</cda>
        <cma>0.00</cma>
        <cla_stall>-0.025</cla_stall>
        <cda_stall>0.0</cda_stall>
        <cma_stall>0.0</cma_stall>
        <area>0.2</area>
        <air_density>1.2041</air_density>
        <cp>-0.084 0 0</cp>
        <forward>0 1 0</forward>
        <upward>0 0 1</upward>
        <link_name>iris_demo::iris::rotor_3</link_name>
      </plugin>
      <plugin name='arducopter_plugin' filename='libArduCopterPlugin.so'>
        <imuName>iris_demo::iris::iris/imu_link::imu_sensor</imuName>
        <connectionTimeoutMaxCount>5</connectionTimeoutMaxCount>
        <rotor id='0'>
          <vel_p_gain>0.01</vel_p_gain>
          <vel_i_gain>0</vel_i_gain>
          <vel_d_gain>0</vel_d_gain>
          <vel_i_max>0</vel_i_max>
          <vel_i_min>0</vel_i_min>
          <vel_cmd_max>2.0</vel_cmd_max>
          <vel_cmd_min>-2.0</vel_cmd_min>
          <jointName>iris_demo::iris::rotor_0_joint</jointName>
          <turningDirection>ccw</turningDirection>
          <rotorVelocitySlowdownSim>1</rotorVelocitySlowdownSim>
        </rotor>
        <rotor id='1'>
          <vel_p_gain>0.01</vel_p_gain>
          <vel_i_gain>0</vel_i_gain>
          <vel_d_gain>0</vel_d_gain>
          <vel_i_max>0</vel_i_max>
          <vel_i_min>0</vel_i_min>
          <vel_cmd_max>2.0</vel_cmd_max>
          <vel_cmd_min>-2.0</vel_cmd_min>
          <jointName>iris_demo::iris::rotor_1_joint</jointName>
          <turningDirection>ccw</turningDirection>
          <rotorVelocitySlowdownSim>1</rotorVelocitySlowdownSim>
        </rotor>
        <rotor id='2'>
          <vel_p_gain>0.01</vel_p_gain>
          <vel_i_gain>0</vel_i_gain>
          <vel_d_gain>0</vel_d_gain>
          <vel_i_max>0</vel_i_max>
          <vel_i_min>0</vel_i_min>
          <vel_cmd_max>2.0</vel_cmd_max>
          <vel_cmd_min>-2.0</vel_cmd_min>
          <jointName>iris_demo::iris::rotor_2_joint</jointName>
          <turningDirection>cw</turningDirection>
          <rotorVelocitySlowdownSim>1</rotorVelocitySlowdownSim>
        </rotor>
        <rotor id='3'>
          <vel_p_gain>0.01</vel_p_gain>
          <vel_i_gain>0</vel_i_gain>
          <vel_d_gain>0</vel_d_gain>
          <vel_i_max>0</vel_i_max>
          <vel_i_min>0</vel_i_min>
          <vel_cmd_max>2.0</vel_cmd_max>
          <vel_cmd_min>-2.0</vel_cmd_min>
          <jointName>iris_demo::iris::rotor_3_joint</jointName>
          <turningDirection>cw</turningDirection>
          <rotorVelocitySlowdownSim>1</rotorVelocitySlowdownSim>
        </rotor>
      </plugin>
      <link name='camera'>
        <pose>0 -0.01 0.07 0.8 -0 1.57</pose>
        <inertial>
          <pose>0 0 0 0 -0 0</pose>
          <mass>0.1</mass>
          <inertia>
            <ixx>0.001</ixx>
            <ixy>0</ixy>
            <ixz>0</ixz>
            <iyy>0.001</iyy>
            <iyz>0</iyz>
            <izz>0.001</izz>
          </inertia>
        </inertial>
        <visual name='visual'>
          <pose>0 0 0 0 -0 0</pose>
          <geometry>
            <cylinder>
              <radius>0.025</radius>
              <length>0.025</length>
            </cylinder>
          </geometry>
          <material>
            <script>
              <uri>file://media/materials/scripts/gazebo.material</uri>
              <name>Gazebo/Grey</name>
            </script>
          </material>
        </visual>
        <sensor name='camera' type='camera'>
          <pose>0 0 0 -1.57 -1.57 0</pose>
          <camera>
            <horizontal_fov>1.0472</horizontal_fov>
            <image>
              <width>640</width>
              <height>480</height>
            </image>
            <clip>
              <near>0.05</near>
              <far>1000</far>
            </clip>
          </camera>
          <always_on>1</always_on>
          <update_rate>10</update_rate>
          <visualize>1</visualize>
          <plugin name='camera_controller' filename='libgazebo_ros_camera.so'>
            <alwaysOn>1</alwaysOn>
            <updateRate>0.0</updateRate>
            <cameraName>webcam</cameraName>
            <imageTopicName>image_raw</imageTopicName>
            <cameraInfoTopicName>camera_info</cameraInfoTopicName>
            <frameName>camera_link</frameName>
            <hackBaseline>0.07</hackBaseline>
            <distortionK1>0.0</distortionK1>
            <distortionK2>0.0</distortionK2>
            <distortionK3>0.0</distortionK3>
            <distortionT1>0.0</distortionT1>
            <distortionT2>0.0</distortionT2>
          </plugin>
        </sensor>
        <self_collide>0</self_collide>
        <enable_wind>0</enable_wind>
        <kinematic>0</kinematic>
      </link>
      <joint name='base_camera_joint' type='revolute'>
        <pose>0 0 0 0 -0 0</pose>
        <parent>iris::iris_demo::gimbal_small_2d::tilt_link</parent>
        <child>camera</child>
        <axis>
          <limit>
            <lower>0</lower>
            <upper>0</upper>
          </limit>
          <xyz expressed_in='__model__'>0 0 1</xyz>
          <dynamics>
            <spring_reference>0</spring_reference>
            <spring_stiffness>0</spring_stiffness>
          </dynamics>
        </axis>
      </joint>
    </model>
    <gravity>0 0 -9.8</gravity>
    <magnetic_field>6e-06 2.3e-05 -4.2e-05</magnetic_field>
    <atmosphere type='adiabatic'/>
    <scene>
      <ambient>0.4 0.4 0.4 1</ambient>
      <background>0.7 0.7 0.7 1</background>
      <shadows>1</shadows>
    </scene>
    <wind/>
    <spherical_coordinates>
      <surface_model>EARTH_WGS84</surface_model>
      <latitude_deg>0</latitude_deg>
      <longitude_deg>0</longitude_deg>
      <elevation>0</elevation>
      <heading_deg>0</heading_deg>
    </spherical_coordinates>
    <model name='heightmap'>
      <static>1</static>
      <link name='link'>
        <collision name='collision'>
          <geometry>
            <heightmap>
              <uri>model://winding_valley_heightmap/materials/textures/heightmap.png</uri>
              <size>1000 1000 25</size>
              <pos>0 0 -10</pos>
              <texture>
                <size>10</size>
                <diffuse>__default__</diffuse>
                <normal>__default__</normal>
              </texture>
              <blend>
                <min_height>0</min_height>
                <fade_dist>0</fade_dist>
              </blend>
            </heightmap>
          </geometry>
          <max_contacts>10</max_contacts>
          <surface>
            <contact>
              <ode/>
            </contact>
            <bounce/>
            <friction>
              <torsional>
                <ode/>
              </torsional>
              <ode/>
            </friction>
          </surface>
        </collision>
        <visual name='visual'>
          <geometry>
            <heightmap>
              <texture>
                <diffuse>file://media/materials/textures/dirt_diffusespecular.png</diffuse>
                <normal>file://media/materials/textures/flat_normal.png</normal>
                <size>10</size>
              </texture>
              <texture>
                <diffuse>file://media/materials/textures/grass_diffusespecular.png</diffuse>
                <normal>file://media/materials/textures/flat_normal.png</normal>
                <size>10</size>
              </texture>
              <texture>
                <diffuse>file://media/materials/textures/fungus_diffusespecular.png</diffuse>
                <normal>file://media/materials/textures/flat_normal.png</normal>
                <size>10</size>
              </texture>
              <blend>
                <min_height>1.5</min_height>
                <fade_dist>10</fade_dist>
              </blend>
              <blend>
                <min_height>10</min_height>
                <fade_dist>5</fade_dist>
              </blend>
              <uri>model://winding_valley_heightmap/materials/textures/heightmap.png</uri>
              <size>1000 1000 25</size>
              <pos>0 0 -10</pos>
            </heightmap>
          </geometry>
        </visual>
        <self_collide>0</self_collide>
        <enable_wind>0</enable_wind>
        <kinematic>0</kinematic>
      </link>
      <pose>-0.716161 -2.9898 0 0 -0 0</pose>
    </model>
    <model name='pickup'>
      <static>1</static>
      <link name='link'>
        <collision name='collision'>
          <pose>0 0 0 0 0 -1.5708</pose>
          <geometry>
            <mesh>
              <uri>model://pickup/meshes/pickup.dae</uri>
            </mesh>
          </geometry>
          <max_contacts>10</max_contacts>
          <surface>
            <contact>
              <ode/>
            </contact>
            <bounce/>
            <friction>
              <torsional>
                <ode/>
              </torsional>
              <ode/>
            </friction>
          </surface>
        </collision>
        <visual name='visual'>
          <pose>0 0 0 0 0 -1.5708</pose>
          <geometry>
            <mesh>
              <uri>model://pickup/meshes/pickup.dae</uri>
            </mesh>
          </geometry>
        </visual>
        <self_collide>0</self_collide>
        <enable_wind>0</enable_wind>
        <kinematic>0</kinematic>
      </link>
      <pose>-21.0146 0.821016 0 0 -0 0</pose>
    </model>
    <state world_name='default'>
      <sim_time>410 245000000</sim_time>
      <real_time>83 672547979</real_time>
      <wall_time>1674848954 225963950</wall_time>
      <iterations>51272</iterations>
      <model name='heightmap'>
        <pose>-0.716161 -2.9898 0 0 -0 0</pose>
        <scale>1 1 1</scale>
        <link name='link'>
          <pose>-0.716161 -2.9898 0 0 -0 0</pose>
          <velocity>0 0 0 0 -0 0</velocity>
          <acceleration>0 0 0 0 -0 0</acceleration>
          <wrench>0 0 0 0 -0 0</wrench>
        </link>
      </model>
      <model name='iris'>
        <pose>-19.5201 1.21461 -7.15052 -0.0288 -0.002127 1.46431</pose>
        <scale>1 1 1</scale>
        <link name='camera'>
          <pose>-19.5106 1.2335 -7.06021 2.36857 0.028798 3.03425</pose>
          <velocity>-5e-06 -1e-06 2.4e-05 -3.9e-05 0.000103 7.5e-05</velocity>
          <acceleration>-0.001452 -0.001476 -0.00012 0.042097 0.186396 0.07951</acceleration>
          <wrench>-0.000145 -0.000148 -1.2e-05 0 -0 0</wrench>
        </link>
        <link name='iris_demo::gimbal_small_2d::base_link'>
          <pose>-19.5122 1.21362 -7.08026 1.56785 0.028798 3.03425</pose>
          <velocity>-7e-06 -1e-06 2.3e-05 3e-06 -8.6e-05 6.5e-05</velocity>
          <acceleration>-0.002517 -0.000993 -0.00088 0.003344 0.014457 -0.109799</acceleration>
          <wrench>-0.000503 -0.000199 -0.000176 0 -0 0</wrench>
        </link>
        <link name='iris_demo::gimbal_small_2d::tilt_link'>
          <pose>-19.5106 1.2335 -7.06021 3.13857 0.028798 3.03425</pose>
          <velocity>-5e-06 -0 2.4e-05 -5.1e-05 -6e-05 6.3e-05</velocity>
          <acceleration>0.001135 -0.001853 -0.000703 0.062782 0.015193 -0.086205</acceleration>
          <wrench>1.1e-05 -1.9e-05 -7e-06 0 -0 0</wrench>
        </link>
        <link name='iris_demo::iris::base_link'>
          <pose>-19.5257 1.2148 -6.95568 -0.0288 -0.002127 1.46431</pose>
          <velocity>-1.8e-05 -2e-06 2.2e-05 5e-06 -8.5e-05 -1e-06</velocity>
          <acceleration>-0.000135 -0.000808 -0.000717 0.002142 -0.001052 6.1e-05</acceleration>
          <wrench>-0.000202 -0.001213 -0.001075 0 -0 0</wrench>
        </link>
        <link name='iris_demo::iris::iris/ground_truth/odometry_sensorgt_link'>
          <pose>-19.5257 1.2148 -6.95568 -0.0288 -0.002127 1.46431</pose>
          <velocity>-1.8e-05 -2e-06 2.2e-05 5e-06 -8.6e-05 -6e-06</velocity>
          <acceleration>-0.000753 -0.001023 -0.000674 0.001629 0.028693 -0.002194</acceleration>
          <wrench>-0.000113 -0.000153 -0.000101 0 -0 0</wrench>
        </link>
        <link name='iris_demo::iris::iris/imu_link'>
          <pose>-19.5257 1.2148 -6.95568 -0.0288 -0.002127 1.46431</pose>
          <velocity>-1.8e-05 -2e-06 2.2e-05 5e-06 -8.6e-05 -6e-06</velocity>
          <acceleration>-0.000738 -0.001023 -0.000678 0.00163 0.028697 -0.002196</acceleration>
          <wrench>-0.000111 -0.000153 -0.000102 0 -0 0</wrench>
        </link>
        <link name='iris_demo::iris::rotor_0'>
          <pose>-19.2939 1.3207 -6.92607 0.007669 -0.027842 -0.30159</pose>
          <velocity>-2e-05 -2e-06 4.3e-05 6e-06 -8.6e-05 -2.9e-05</velocity>
          <acceleration>-0.000399 -0.000798 -0.004012 -0.064345 0.034145 -0.001952</acceleration>
          <wrench>-1e-05 -2e-05 -0.0001 0 -0 0</wrench>
        </link>
        <link name='iris_demo::iris::rotor_1'>
          <pose>-19.739 1.10682 -6.93872 -0.01857 -0.022117 0.665756</pose>
          <velocity>-1.9e-05 -1e-06 3e-06 6e-06 -8.6e-05 -2.9e-05</velocity>
          <acceleration>-0.000371 -0.00123 0.002393 0.112368 0.102612 0.003077</acceleration>
          <wrench>-9e-06 -3.1e-05 6e-05 0 -0 0</wrench>
        </link>
        <link name='iris_demo::iris::rotor_2'>
          <pose>-19.7312 1.36747 -6.93874 0.009206 -0.027372 -0.357282</pose>
          <velocity>-1.9e-05 -1e-06 5e-06 6e-06 -8.6e-05 -2.9e-05</velocity>
          <acceleration>-0.000622 -0.001228 0.00231 -0.074086 0.041735 -0.002246</acceleration>
          <wrench>-1.6e-05 -3.1e-05 5.8e-05 0 -0 0</wrench>
        </link>
        <link name='iris_demo::iris::rotor_3'>
          <pose>-19.3414 1.0643 -6.9272 0.02677 0.010832 -1.98797</pose>
          <velocity>-2e-05 -2e-06 3.7e-05 6e-06 -8.6e-05 -2.9e-05</velocity>
          <acceleration>-0.000159 -0.000854 -0.003372 0.088828 0.215303 0.002291</acceleration>
          <wrench>-4e-06 -2.1e-05 -8.4e-05 0 -0 0</wrench>
        </link>
      </model>
      <model name='person_standing_0'>
        <pose>-21.1043 4.71597 -7.15686 -0 -1e-06 0.000441</pose>
        <scale>1 1 1</scale>
        <link name='link'>
          <pose>-21.1043 4.71597 -7.15686 -0 -1e-06 0.000441</pose>
          <velocity>0 0 0 0 -0 0</velocity>
          <acceleration>2.19494 -1.52944 1.46305 -1.47972 0.867386 3.09657</acceleration>
          <wrench>175.595 -122.355 117.044 0 -0 0</wrench>
        </link>
      </model>
      <model name='pickup'>
        <pose>-19.5536 9.71975 -7.02989 0 -0 0</pose>
        <scale>1 1 1</scale>
        <link name='link'>
          <pose>-19.5536 9.71975 -7.02989 0 -0 0</pose>
          <velocity>0 0 0 0 -0 0</velocity>
          <acceleration>0 0 0 0 -0 0</acceleration>
          <wrench>0 0 0 0 -0 0</wrench>
        </link>
      </model>
      <light name='sun'>
        <pose>0 0 10 0 -0 0</pose>
      </light>
    </state>
    <gui fullscreen='0'>
      <camera name='user_camera'>
        <pose>-21.5761 -7.9124 -0.893338 0 0.503457 1.18019</pose>
        <view_controller>orbit</view_controller>
        <projection_type>perspective</projection_type>
      </camera>
    </gui>
    <model name='person_standing_0'>
      <link name='link'>
        <inertial>
          <pose>0 -0.1 0.95 0 -0 0</pose>
          <mass>80</mass>
          <inertia>
            <ixx>24.88</ixx>
            <ixy>0</ixy>
            <ixz>0</ixz>
            <iyy>25.73</iyy>
            <iyz>0</iyz>
            <izz>2.48</izz>
          </inertia>
        </inertial>
        <self_collide>0</self_collide>
        <enable_wind>0</enable_wind>
        <kinematic>0</kinematic>
        <pose>0 0 0 0 -0 0</pose>
        <gravity>1</gravity>
        <visual name='visual'>
          <pose>0 0 0.02 0.04 -0 0</pose>
          <geometry>
            <mesh>
              <uri>model://person_standing/meshes/standing.dae</uri>
            </mesh>
          </geometry>
          <material>
            <shader type='pixel'>
              <normal_map>__default__</normal_map>
            </shader>
            <script>
              <name>ModelPreview_3::link::visual_MATERIAL_</name>
              <uri>__default__</uri>
            </script>
            <ambient>0 0 1 0</ambient>
            <diffuse>0 0 0 1</diffuse>
            <specular>0 0 0 1</specular>
            <emissive>0 0 0 1</emissive>
          </material>
          <transparency>0</transparency>
          <cast_shadows>1</cast_shadows>
        </visual>
        <collision name='bottom'>
          <laser_retro>0</laser_retro>
          <max_contacts>10</max_contacts>
          <pose>0 -0.1 0.01 0 -0 0</pose>
          <geometry>
            <box>
              <size>0.5 0.35 0.02</size>
            </box>
          </geometry>
          <surface>
            <friction>
              <ode>
                <mu>1</mu>
                <mu2>1</mu2>
                <fdir1>0 0 0</fdir1>
                <slip1>0</slip1>
                <slip2>0</slip2>
              </ode>
              <torsional>
                <coefficient>1</coefficient>
                <patch_radius>0</patch_radius>
                <surface_radius>0</surface_radius>
                <use_patch_radius>1</use_patch_radius>
                <ode>
                  <slip>0</slip>
                </ode>
              </torsional>
            </friction>
            <bounce>
              <restitution_coefficient>0</restitution_coefficient>
              <threshold>1e+06</threshold>
            </bounce>
            <contact>
              <collide_without_contact>0</collide_without_contact>
              <collide_without_contact_bitmask>1</collide_without_contact_bitmask>
              <collide_bitmask>1</collide_bitmask>
              <ode>
                <soft_cfm>0</soft_cfm>
                <soft_erp>0.2</soft_erp>
                <kp>1e+13</kp>
                <kd>1</kd>
                <max_vel>0.01</max_vel>
                <min_depth>0</min_depth>
              </ode>
              <bullet>
                <split_impulse>1</split_impulse>
                <split_impulse_penetration_threshold>-0.01</split_impulse_penetration_threshold>
                <soft_cfm>0</soft_cfm>
                <soft_erp>0.2</soft_erp>
                <kp>1e+13</kp>
                <kd>1</kd>
              </bullet>
            </contact>
          </surface>
        </collision>
        <collision name='person'>
          <laser_retro>0</laser_retro>
          <max_contacts>10</max_contacts>
          <pose>0 0 0.02 0.04 -0 0</pose>
          <geometry>
            <mesh>
              <uri>/home/super/.gazebo/models/person_standing/meshes/standing.dae</uri>
              <scale>1 1 1</scale>
            </mesh>
          </geometry>
          <surface>
            <friction>
              <ode>
                <mu>1</mu>
                <mu2>1</mu2>
                <fdir1>0 0 0</fdir1>
                <slip1>0</slip1>
                <slip2>0</slip2>
              </ode>
              <torsional>
                <coefficient>1</coefficient>
                <patch_radius>0</patch_radius>
                <surface_radius>0</surface_radius>
                <use_patch_radius>1</use_patch_radius>
                <ode>
                  <slip>0</slip>
                </ode>
              </torsional>
            </friction>
            <bounce>
              <restitution_coefficient>0</restitution_coefficient>
              <threshold>1e+06</threshold>
            </bounce>
            <contact>
              <collide_without_contact>0</collide_without_contact>
              <collide_without_contact_bitmask>1</collide_without_contact_bitmask>
              <collide_bitmask>1</collide_bitmask>
              <ode>
                <soft_cfm>0</soft_cfm>
                <soft_erp>0.2</soft_erp>
                <kp>1e+13</kp>
                <kd>1</kd>
                <max_vel>0.01</max_vel>
                <min_depth>0</min_depth>
              </ode>
              <bullet>
                <split_impulse>1</split_impulse>
                <split_impulse_penetration_threshold>-0.01</split_impulse_penetration_threshold>
                <soft_cfm>0</soft_cfm>
                <soft_erp>0.2</soft_erp>
                <kp>1e+13</kp>
                <kd>1</kd>
              </bullet>
            </contact>
          </surface>
        </collision>
      </link>
      <static>0</static>
      <allow_auto_disable>1</allow_auto_disable>
      <pose>-22.8895 -9.05947 0 0 -0 0</pose>
    </model>
  </world>
</sdf>
